Workbook

Sheet Admin
A1: Company Categores | C1: Strat | E1: Priority | G1: Status | I1: Aviation Lookup
A2: Parts Supplier | C2: No Alignment | E2: Low | G2: Done | I2: Category | J2: Scope of Work
A3: AMO | C3: Approved Supplier | E3: Medium | G3: Contacted - Email | I3: A | J3: Line maintenance on aircraft airframes (release to service, minor assembly, certifying install and test/ferry flights)
A4: AMO - Heli | C4: Client | E4: High | G4: NTC | I4: B | J4: Component-level maintenance for airframes and accessories (rotorcraft excluded from engine)
A5: Charter | C5: Partnership | E5: Imminent | G5: Investigate | I5: C | J5: On‑wing maintenance for engines (non‑rotorcraft), including test flight release
A6: Charter - Heli | C6: Convert - Serial Number | G6: DNC | I6: D | J6: Rack-level engine work (overhaul, repair, modifications), plus manufacture of parts under CAR 21
A7: Insurance | G7: Closed | I7: E | J7: Rotorcraft and rotorcraft‑engine maintenance (airframe/engine installs, overhaul, rotors, test‑flight release)
A8: Underwriter | G8: Cape Town | I8: W | J8: Installation and maintenance of aircraft electrical, instrument, and radio systems across all aircraft classes
A9: Brokers | G9: Last Order | I9: X | J9: Overhaul, repair, testing, modification, and limited manufacture of equipment, instruments, components, accessories, auxiliaries, parts (e.g. propellers class X4, welding class X5)
A10: Flight School | G10: Edrich
A11: Commercial | G11: Likely Closed
A12: Motorsport

Sheet Company_Cat
A1: C_ID | B1: Company | C1: QuickNooks_Name | D1: Last_Order_Date | E1: Category | F1: Strat | G1: Priority | H1: Status | I1: LoadDate | J1: Checked | K1: Website
A2: 1 | B2: 208 Aviation CC | C2: 208 Aviation CC | D2: 45810 | E2: Unspecified | G2: Low | H2: Investigate | I2: 1970-01-01 | K2: https://www.santam.co.za/insurance/for-specialised-risks/aviation/
A3: 2 | B3: 360 Aviation | C3: 360 Aviation | E3: AMO - Heli | F3: Client | G3: Low | H3: Contacted | I3: 2025-07-01 | K3: https://itoo.co.za
A4: 3 | B4: 43 Air School | C4: 43 Air School | E4: Unspecified | G4: Low | H4: Investigate | I4: 1970-01-01
A5: 4 | B5: 4aviators | C5: 4aviators | E5: Flight School | G5: Low | H5: Unknown | I5: 1970-01-01 | K5: https://www.infinitiafrica.com
A6: 5 | B6: Absolute Service Centre (Pty) Ltd | C6: Absolute Service Centre | D6: 42247 | E6: Unspecified | G6: Low | H6: Investigate | I6: 1970-01-01
A7: 6 | B7: Academy Air | C7: Acadamy Air Charl Truter | D7: 41550 | E7: Unspecified | G7: Low | H7: Investigate | I7: 1970-01-01 | K7: https://www.aig.com/home/risk-solutions/business/specialty-risks/aerospace-and-aviation#accordion-df98a3f1db-item-e1731f5793
A8: 7 | B8: Acher Aviation | C8: Acher Aviation Helicopters | D8: 45859 | E8: Unspecified | G8: Low | H8: Investigate | I8: 1970-01-01
A9: 8 | B9: ADT Heliworx | C9: ADT Heliworx | E9: Unspecified | G9: Low | H9: Investigate | I9: 1970-01-01
A10: 9 | B10: Advanced Technologies & Engineering(PTY)Ltd t/a Paramount Aerospace Systemes | C10: Advanced Technologies & Engineering(PTY)Ltd t/a Paramount Aerospace Systemes | E10: Unspecified | G10: Low | H10: Investigate | I10: 1970-01-01
A11: 10 | B11: Adventure Air | C11: Adventure Air | D11: 44586 | E11: Unspecified | G11: Low | H11: Investigate | I11: 1970-01-01
A12: 11 | B12: Aero Electrical Solutions | C12: Aero Electrical Solutions | E12: Unspecified | G12: Low | H12: Investigate | I12: 1970-01-01
A13: 12 | B13: Aero Engineering and Powerplant | C13: Aero Engineering and Powerplant | E13: Unspecified | G13: Low | H13: Investigate | I13: 1970-01-01
A14: 13 | B14: Aero Maintenance Centre CC | C14: Aero Maintenance Centre CC | E14: Unspecified | G14: Low | H14: Investigate | I14: 1970-01-01
A15: 14 | B15: Aero Natal (Pty) Ltd | C15: Aero Natal (Pty) Ltd | E15: Unspecified | G15: Low | H15: Investigate | I15: 1970-01-01
A16: 15 | B16: Aero Services Pty Ltd | C16: Aero Services Pty Ltd | E16: Unspecified | G16: Low | H16: Investigate | I16: 1970-01-01
A17: 16 | B17: Aero Test NDT cc | C17: Aero Test NDT cc | E17: Unspecified | G17: Low | H17: Investigate | I17: 1970-01-01
A18: 17 | B18: AEROCORPORATION AVIATION SERVICES AMO (Pty) Ltd | C18: AEROCORPORATION AVIATION SERVICES AMO (Pty) Ltd | E18: Unspecified | G18: Low | H18: Investigate | I18: 1970-01-01 | K18: https://www.flightsure.co.za/
A19: 18 | B19: AEROMARITIME MEDITERRANEAN- MALTA | C19: AEROMARITIME MEDITERRANEAN- MALTA | E19: Unspecified | G19: Low | H19: Investigate | I19: 1970-01-01 | K19: https://www.arcaviation.co.za/
A20: 19 | B20: Aeronautic Solutions (Pty) Ltd | C20: Aeronautic Solutions (Pty) Ltd | E20: Unspecified | G20: Low | H20: Investigate | I20: 1970-01-01
A21: 20 | B21: Aeronautical Aviation | C21: Aeronautical Aviation | E21: Unspecified | G21: Low | H21: Investigate | I21: 1970-01-01
A22: 21 | B22: Aeronexus Corporate (PTY) LTD | C22: Aeronexus | D22: 38818 | E22: Unspecified | G22: Low | H22: Investigate | I22: 1970-01-01
A23: 22 | B23: Aerospace Electroplating CC | C23: Aerospace Electroplating CC | E23: Unspecified | G23: Low | H23: Investigate | I23: 1970-01-01 | K23: https://pilotinsure.co.za
A24: 23 | B24: Aerotec | C24: Aerotec | E24: Unspecified | G24: Low | H24: Investigate | I24: 1970-01-01
A25: 24 | B25: AEROTRIC (Pty)Ltd | C25: AEROTRIC (Pty)Ltd | E25: Unspecified | G25: Low | H25: Investigate | I25: 1970-01-01 | K25: https://4aviators.com/
A26: 25 | B26: Aeroweld & Supplies | C26: Aeroweld & Supplies | E26: Unspecified | G26: Low | H26: Investigate | I26: 1970-01-01 | K26: https://agmfsg.co.za/specialist-insurance-commercial/
A27: 26 | B27: Afritec Aviation Services | C27: Afritec Aviation Services | E27: Unspecified | G27: Low | H27: Investigate | I27: 1970-01-01
A28: 27 | B28: Against The Wind | C28: Against The Wind | E28: Unspecified | G28: Low | H28: Investigate | I28: 1970-01-01
A29: 28 | B29: AGM | C29: AGM | E29: Insurance | F29: Approved Supplier | G29: Low | H29: Unknown | I29: 1970-01-01
A30: 29 | B30: Aiforce Turbine Services Texas | C30: Aiforce Turbine Services Texas | E30: Unspecified | G30: Low | H30: Investigate | I30: 1970-01-01
A31: 30 | B31: AIG South Africa | C31: AIG South Africa | E31: Insurance | F31: Approved Supplier | G31: Low | H31: Done | I31: 2025-07-14 | J31: 1
A32: 31 | B32: AIR EXPRESS ALGERIA | C32: AIR EXPRESS ALGERIA | E32: Unspecified | G32: Low | H32: Investigate | I32: 1970-01-01
A33: 32 | B33: Air Hart Aircraft CC. | C33: Air Hart Aircraft | D33: 37512 | E33: Unspecified | G33: Low | H33: Investigate | I33: 1970-01-01
A34: 33 | B34: Air Mauritius Ltd | C34: Air Mauritius Ltd | E34: Unspecified | G34: Low | H34: Investigate | I34: 1970-01-01
A35: 34 | B35: Air Serve | C35: Air Serve | E35: Unspecified | G35: Low | H35: Investigate | I35: 1970-01-01
A36: 35 | B36: Airborne Insurance Consultants (PSG Insure) | C36: Airborne Insurance Consultants (PSG Insure) | E36: Brokers | F36: Approved Supplier | G36: Low | H36: Unknown | I36: 1970-01-01
A37: 36 | B37: Airbus Southern Africa (Pty) Ltd | C37: Airbus Southern Africa (Pty) Ltd | E37: Unspecified | G37: Low | H37: Investigate | I37: 1970-01-01
A38: 37 | B38: AIRCRAFT FUSELAGE REPAIRS | C38: AIRCRAFT FUSELAGE REPAIRS | E38: Unspecified | G38: Low | H38: Investigate | I38: 1970-01-01
A39: 38 | B39: Aircraft Instruments CC | C39: Aircraft Instruments CC | E39: Unspecified | G39: Low | H39: Investigate | I39: 1970-01-01
A40: 39 | B40: Aircraft Maintenance @ work | C40: Aircraft Maintenance @ work | E40: Unspecified | G40: Low | H40: Investigate | I40: 1970-01-01
...

Sheet Order Dates
A1: Company_QuickBooks+ | B1: Order_Dates | C1: Once-Off | D1: Captured
A2: Acher Aviation Helicopters | B2: 45859 | D2: =IFERROR(VLOOKUP($A2,Company_Cat!$C$2:$C$623,1,FALSE),"")
A3: ms FAST DEVELOPMENT CC | B3: 45855 | D3: =IFERROR(VLOOKUP($A3,Company_Cat!$C$2:$C$623,1,FALSE),"")
A4: ms Pablo Clark | B4: 45855 | D4: =IFERROR(VLOOKUP($A4,Company_Cat!$C$2:$C$623,1,FALSE),"")
A5: ms Stradale Motorsport | B5: 45855 | D5: =IFERROR(VLOOKUP($A5,Company_Cat!$C$2:$C$623,1,FALSE),"")
A6: Skytrim rico | B6: 45855 | D6: =IFERROR(VLOOKUP($A6,Company_Cat!$C$2:$C$623,1,FALSE),"")
A7: capital air | B7: 45853 | D7: =IFERROR(VLOOKUP($A7,Company_Cat!$C$2:$C$623,1,FALSE),"")
A8: Sky Hunter South Africa | B8: 45848 | D8: =IFERROR(VLOOKUP($A8,Company_Cat!$C$2:$C$623,1,FALSE),"")
A9: Alton Aero Eng | B9: 45840 | D9: =IFERROR(VLOOKUP($A9,Company_Cat!$C$2:$C$623,1,FALSE),"")
A10: TAM | B10: 45838 | D10: =IFERROR(VLOOKUP($A10,Company_Cat!$C$2:$C$623,1,FALSE),"")
A11: Aviation Rebuilders | B11: 45827 | D11: =IFERROR(VLOOKUP($A11,Company_Cat!$C$2:$C$623,1,FALSE),"")
A12: Heli-Fix cc | B12: 45826 | D12: =IFERROR(VLOOKUP($A12,Company_Cat!$C$2:$C$623,1,FALSE),"")
A13: ms Nishal Autonische | B13: 45819 | D13: =IFERROR(VLOOKUP($A13,Company_Cat!$C$2:$C$623,1,FALSE),"")
... A320: Acryl Form | B320: 40221 | D320: =IFERROR(VLOOKUP($A320,Company_Cat!$C$2:$C$623,1,FALSE),"")
A321: A R Cook | B321: 40219 | C321: 1 | D321: =IFERROR(VLOOKUP($A321,Company_Cat!$C$2:$C$623,1,FALSE),"")
A322: Harry Leach Trust | B322: 40219 | D322: =IFERROR(VLOOKUP($A322,Company_Cat!$C$2:$C$623,1,FALSE),"")
A323: ms Misubishi Raptor Engineering | B323: 40200 | D323: =IFERROR(VLOOKUP($A323,Company_Cat!$C$2:$C$623,1,FALSE),"")
A324: KAE | B324: 40196 | D324: =IFERROR(VLOOKUP($A324,Company_Cat!$C$2:$C$623,1,FALSE),"")
A325: Vernon Smith | B325: 40161 | D325: =IFERROR(VLOOKUP($A325,Company_Cat!$C$2:$C$623,1,FALSE),"")
A326: ms RG Motorsport | B326: 40135 | D326: =IFERROR(VLOOKUP($A326,Company_Cat!$C$2:$C$623,1,FALSE),"")
A327: Diesel Aviation | B327: 40092 | D327: =IFERROR(VLOOKUP($A327,Company_Cat!$C$2:$C$623,1,FALSE),"")
A328: Spingbok Aviation | B328: 40084 | D328: =IFERROR(VLOOKUP($A328,Company_Cat!$C$2:$C$623,1,FALSE),"")
A329: Omni | B329: 40052 | D329: =IFERROR(VLOOKUP($A329,Company_Cat!$C$2:$C$623,1,FALSE),"")
A330: DENEL SAAB AEROSTRUCTURES (PTY) LTD | B330: 40040 | D330: =IFERROR(VLOOKUP($A330,Company_Cat!$C$2:$C$623,1,FALSE),"")
A331: Duraset Visagie | B331: 40022 | D331: =IFERROR(VLOOKUP($A331,Company_Cat!$C$2:$C$623,1,FALSE),"")
A332: ms Porche Dave Fourie | B332: 39994 | D332: =IFERROR(VLOOKUP($A332,Company_Cat!$C$2:$C$623,1,FALSE),"")
A333: ms Village Auto | B333: 39975 | D333: =IFERROR(VLOOKUP($A333,Company_Cat!$C$2:$C$623,1,FALSE),"")
... A554: Hunting Aviation | B554: 35326 | D554: =IFERROR(VLOOKUP($A554,Company_Cat!$C$2:$C$623,1,FALSE),"")

Sheet Sheet1
A1: Abbot Cars | B1: ms Abbot Cars | C1: 41568
A2: Spannerworx | B2: ms Alpha Romeo Trevor Tuck | C2: 42032
A3: Allwagen | B3: ms Allwagen | C3: 44376
A4: Exclusive Conversions | B4: ms Anton Decker
A5: Auby Boys Racing | B5: ms Auby Boys Racing | C5: 41002
A6: Auto Associates | B6: ms Auto Associates | C6: 41724
A7: AutoCom | B7: ms AutoCom | C7: 41574
A8: Autohaus Angel | B8: ms Autohaus Angel | C8: 43735
A9: Azoic Panelbeaters | B9: ms Azoic | C9: 42563
A10: Seven mile trading 424 cc T/A B Speed | B10: ms B Speed | C10: 44440
A11: Randfontein Paneelkloppers | B11: ms Ben Morgenrood | C11: 40751
A12: Wayne Niz | B12: ms BMW Wayne Niz | C12: 41225
A13: Evolution 2 Motorsport | B13: ms BMW Kaye Eddie | C13: 38182
A14: BMW Montana | B14: ms BMW Montana | C14: 44235
A15: BMW South Africa (SA) (Pty) Ltd | B15: ms BMW Motorsport | C15: 39447
A16: Riaan | B16: ms BMW Riaan | C16: 39447
... A47: JSR | B47: ms Honda JSR | C47: 40581

Sheet Company_Contacts
A1: C_ID | B1: Company | C1: Status | D1: FirstName | E1: Surname | F1: Position | G1: Cellnumber | H1: Email | I1: Landline
A2: =IFERROR(VLOOKUP($B2,Company_Cat!$B$2:$E$623,2,FALSE),"") | B2: Flightsure | C2: =IFERROR(VLOOKUP($B2,Company_Cat!$B$2:$H$623,6,FALSE),"") | D2: Dorrien Andrews | F2: Director | G2: 27832269672 | H2: dorrien@flightsure.co.za
A3: =IFERROR(VLOOKUP($B3,Company_Cat!$B$2:$E$623,2,FALSE),"") | B3: Flightsure | C3: =IFERROR(VLOOKUP($B3,Company_Cat!$B$2:$H$623,6,FALSE),"") | D3: Mandy Coetzer | F3: Director | G3: 27824483643 | H3: mandy@flightsure.co.za
A4: =IFERROR(VLOOKUP($B4,Company_Cat!$B$2:$E$623,2,FALSE),"") | B4: Flightsure | C4: =IFERROR(VLOOKUP($B4,Company_Cat!$B$2:$H$623,6,FALSE),"") | D4: Gaile Mendes | F4: Director | G4: 27828501857 | H4: gaile@flightsure.co.za
A5: =IFERROR(VLOOKUP($B5,Company_Cat!$B$2:$E$623,2,FALSE),"") | B5: Flightsure | C5: =IFERROR(VLOOKUP($B5,Company_Cat!$B$2:$H$623,6,FALSE),"") | D5: Glenn Andrews | F5: Director | G5: 27832597581
A6: =IFERROR(VLOOKUP($B6,Company_Cat!$B$2:$E$623,2,FALSE),"") | B6: Arc Aviation (Aircraft Risk Company) | C6: =IFERROR(VLOOKUP($B6,Company_Cat!$B$2:$H$623,6,FALSE),"") | D6: Stuart Farquhar | F6: MD | G6: 27824432633 | H6: stuart@arcaviation.co.za
A7: =IFERROR(VLOOKUP($B7,Company_Cat!$B$2:$E$623,2,FALSE),"") | B7: Arc Aviation (Aircraft Risk Company) | C7: =IFERROR(VLOOKUP($B7,Company_Cat!$B$2:$H$623,6,FALSE),"") | D7: Darren Gallias | F7: Director - Claims Manager | G7: 27833777190 | H7: darren@arcaviation.co.za
A8: =IFERROR(VLOOKUP($B8,Company_Cat!$B$2:$E$623,2,FALSE),"") | B8: Arc Aviation (Aircraft Risk Company) | C8: =IFERROR(VLOOKUP($B8,Company_Cat!$B$2:$H$623,6,FALSE),"") | D8: Dylan Knight | F8: New Business Broker | G8: 27725290273 | H8: dylan@arcaviation.co.za
A9: =IFERROR(VLOOKUP($B9,Company_Cat!$B$2:$E$623,2,FALSE),"") | B9: Arc Aviation (Aircraft Risk Company) | C9: =IFERROR(VLOOKUP($B9,Company_Cat!$B$2:$H$623,6,FALSE),"") | D9: Tshidi Ntsoseng | F9: Accounts | G9: 27734323112 | H9: tshidi@arcaviation.co.za
A10: =IFERROR(VLOOKUP($B10,Company_Cat!$B$2:$E$623,2,FALSE),"") | B10: Arc Aviation (Aircraft Risk Company) | C10: =IFERROR(VLOOKUP($B10,Company_Cat!$B$2:$H$623,6,FALSE),"") | D10: Clement Sibiya | F10: Accounts Executive | G10: 27713391251 | H10: clement@arcaviation.co.za
A11: =IFERROR(VLOOKUP($B11,Company_Cat!$B$2:$E$623,2,FALSE),"") | B11: Arc Aviation (Aircraft Risk Company) | C11: =IFERROR(VLOOKUP($B11,Company_Cat!$B$2:$H$623,6,FALSE),"") | D11: Janice Ray | F11: Senior Accounts Exec | G11: 27832926917 | H11: janice@arcaviation.co.za
A12: =IFERROR(VLOOKUP($B12,Company_Cat!$B$2:$E$623,2,FALSE),"") | B12: Arc Aviation (Aircraft Risk Company) | C12: =IFERROR(VLOOKUP($B12,Company_Cat!$B$2:$H$623,6,FALSE),"") | D12: Janette Harris | F12: Senior Accounts & Compliance Manager | G12: 27761580797 | H12: janette@arcaviation.co.za
A13: =IFERROR(VLOOKUP($B13,Company_Cat!$B$2:$E$623,2,FALSE),"") | B13: iTOO Special Risks (Hollard) | C13: =IFERROR(VLOOKUP($B13,Company_Cat!$B$2:$H$623,6,FALSE),"") | D13: Lorenzio Bettini | F13: Senior Underwriter | H13: LorenzioB@itoo.co.za
A14: =IFERROR(VLOOKUP($B14,Company_Cat!$B$2:$E$623,2,FALSE),"") | B14: Infiniti Insurance | C14: =IFERROR(VLOOKUP($B14,Company_Cat!$B$2:$H$623,6,FALSE),"") | D14: Carly Ranger | F14: Aviation Broker | G14: 27828570291 | H14: carlyr@infinitiaviation.co.za
A15: =IFERROR(VLOOKUP($B15,Company_Cat!$B$2:$E$623,2,FALSE),"") | B15: Infiniti Insurance | C15: =IFERROR(VLOOKUP($B15,Company_Cat!$B$2:$H$623,6,FALSE),"") | D15: Belinda Hawkins | F15: General Manager - Divisonal Head | H15: belindah@infinitiafrica.com | I15: 27117181200
A16: =IFERROR(VLOOKUP($B16,Company_Cat!$B$2:$E$623,2,FALSE),"") | B16: Infiniti Insurance | C16: =IFERROR(VLOOKUP($B16,Company_Cat!$B$2:$H$623,6,FALSE),"") | D16: Sharon Paterson | F16: CEO
A17: =IFERROR(VLOOKUP($B17,Company_Cat!$B$2:$E$623,2,FALSE),"") | B17: AIG South Africa | C17: =IFERROR(VLOOKUP($B17,Company_Cat!$B$2:$H$623,6,FALSE),"") | D17: Johannseburg Office | F17: Admin | G17: 27861488864
A18: =IFERROR(VLOOKUP($B18,Company_Cat!$B$2:$E$623,2,FALSE),"") | B18: iTOO Special Risks (Hollard) | C18: =IFERROR(VLOOKUP($B18,Company_Cat!$B$2:$H$623,6,FALSE),"") | D18: Willie | E18: Jansen van Rensburg | F18: Business Head - Claims | H18: WillieJ@itoo.co.za
A19: =IFERROR(VLOOKUP($B19,Company_Cat!$B$2:$E$623,2,FALSE),"") | B19: iTOO Special Risks (Hollard) | C19: =IFERROR(VLOOKUP($B19,Company_Cat!$B$2:$H$623,6,FALSE),"") | D19: Warwick | E19: Goldie | F19: Chief Underwriting Officer | H19: WarwickG@itoo.co.za
A20: =IFERROR(VLOOKUP($B20,Company_Cat!$B$2:$E$623,2,FALSE),"") | B20: iTOO Special Risks (Hollard) | C20: =IFERROR(VLOOKUP($B20,Company_Cat!$B$2:$H$623,6,FALSE),"") | D20: Jonathan | E20: Healy | F20: Managing Executive | H20: JonathanH@Itoo.co.za
A21: =IFERROR(VLOOKUP($B21,Company_Cat!$B$2:$E$623,2,FALSE),"") | B21: Orsmond Aviation | C21: =IFERROR(VLOOKUP($B21,Company_Cat!$B$2:$H$623,6,FALSE),"") | D21: Admin | G21: 27583035261 | H21: info@orsmondaviation.co.za
A22: =IFERROR(VLOOKUP($B22,Company_Cat!$B$2:$E$623,2,FALSE),"") | B22: MCC Aviation(PTY) Ltd | C22: =IFERROR(VLOOKUP($B22,Company_Cat!$B$2:$H$623,6,FALSE),"") | D22: Admin | H22: info@flymcc.co.za
A23: =IFERROR(VLOOKUP($B23,Company_Cat!$B$2:$E$623,2,FALSE),"") | B23: MCC Aviation(PTY) Ltd | C23: =IFERROR(VLOOKUP($B23,Company_Cat!$B$2:$H$623,6,FALSE),"") | D23: Micheal | E23: Goodwin | F23: General Manager | H23: mike.goodwin@flymcc.co.za
A24: =IFERROR(VLOOKUP($B24,Company_Cat!$B$2:$E$623,2,FALSE),"") | B24: Capital Air (Pty) Ltd | C24: =IFERROR(VLOOKUP($B24,Company_Cat!$B$2:$H$623,6,FALSE),"") | D24: Admin | H24: info@capitalairsa.com | I24: 27118270335
A25: =IFERROR(VLOOKUP($B25,Company_Cat!$B$2:$E$623,2,FALSE),"") | B25: MCC Aviation(PTY) Ltd | C25: =IFERROR(VLOOKUP($B25,Company_Cat!$B$2:$H$623,6,FALSE),"") | D25: Sean | E25: Murphy | F25: Helicopter AMO Manager | H25: sean.murphy@flymcc.co.za
A26: =IFERROR(VLOOKUP($B26,Company_Cat!$B$2:$E$623,2,FALSE),"") | B26: NAC Helicopter Division | C26: =IFERROR(VLOOKUP($B26,Company_Cat!$B$2:$H$623,6,FALSE),"") | D26: Ashley | E26: Spolander | F26: Helicopter Maintenance & Engine Shop Manager | H26: ashley.spolander@nac.co.za | I26: 27113452500
A27: =IFERROR(VLOOKUP($B27,Company_Cat!$B$2:$E$623,2,FALSE),"") | B27: SANPARKS | C27: =IFERROR(VLOOKUP($B27,Company_Cat!$B$2:$H$623,6,FALSE),"") | D27: Charles | E27: Phahlane | F27: Senior Communications Manager | G27: 27828568188 | H27: charles.phahlane@sanparks.org | I27: 27124265000
A28: =IFERROR(VLOOKUP($B28,Company_Cat!$B$2:$E$623,2,FALSE),"") | B28: Transvaal Aircraft Maintenance (Pty) Ltd | C28: =IFERROR(VLOOKUP($B28,Company_Cat!$B$2:$H$623,6,FALSE),"") | D28: Chris | E28: Korrf | I28: 27125671191
A29: =IFERROR(VLOOKUP($B29,Company_Cat!$B$2:$E$623,2,FALSE),"") | B29: Emperor Aviation Pty(Ltd) | C29: =IFERROR(VLOOKUP($B29,Company_Cat!$B$2:$H$623,6,FALSE),"") | D29: Paul | E29: Sankey | F29: CEO/Accountable Manager | G29: 27824971701 | H29: paul@emperoraviation.co.za
A30: =IFERROR(VLOOKUP($B30,Company_Cat!$B$2:$E$623,2,FALSE),"") | B30: PRECISION AVIATION SERVICES (PTY) Ltd | C30: =IFERROR(VLOOKUP($B30,Company_Cat!$B$2:$H$623,6,FALSE),"") | D30: Rikus | E30: Botha | H30: riks@pasaviation.co.za | I30: 27125430371
A31: =IFERROR(VLOOKUP($B31,Company_Cat!$B$2:$E$623,2,FALSE),"") | B31: BAC Aviation (Pty) Ltd | C31: =IFERROR(VLOOKUP($B31,Company_Cat!$B$2:$H$623,6,FALSE),"") | D31: Tremayne | E31: Thompson | F31: CEO/Accountable Manager | G31: 27837782635 | H31: tthompson@bacheli.com
A32: =IFERROR(VLOOKUP($B32,Company_Cat!$B$2:$E$623,2,FALSE),"") | B32: Lady Lori Kenya Limited | C32: =IFERROR(VLOOKUP($B32,Company_Cat!$B$2:$H$623,6,FALSE),"") | D32: Admin | G32: 27729850600 | H32: operations@flyladylori.com
A33: =IFERROR(VLOOKUP($B33,Company_Cat!$B$2:$E$623,2,FALSE),"") | B33: Ferreira Aviation CC | C33: =IFERROR(VLOOKUP($B33,Company_Cat!$B$2:$H$623,6,FALSE),"") | D33: Stanley | E33: Schimper | F33: Bloemfontein | G33: 27835576120 | H33: stanley@ferreiraaviation.co.za
A34: =IFERROR(VLOOKUP($B34,Company_Cat!$B$2:$E$623,2,FALSE),"") | B34: Ferreira Aviation CC | C34: =IFERROR(VLOOKUP($B34,Company_Cat!$B$2:$H$623,6,FALSE),"") | D34: Wyndham | E34: Ferreira | F34: Bloemfontein | G34: 27832620313 | H34: wyndham@ferreiraaviation.co.za
A35: =IFERROR(VLOOKUP($B35,Company_Cat!$B$2:$E$623,2,FALSE),"") | B35: Ferreira Aviation CC | C35: =IFERROR(VLOOKUP($B35,Company_Cat!$B$2:$H$623,6,FALSE),"") | D35: JP | F35: George | G35: 27843313964 | H35: jp@ferreiraaviation.co.za
A36: =IFERROR(VLOOKUP($B36,Company_Cat!$B$2:$E$623,2,FALSE),"") | B36: Lowveld Aircraft Services CC | C36: =IFERROR(VLOOKUP($B36,Company_Cat!$B$2:$H$623,6,FALSE),"") | D36: THOMAS | E36: WILLOWS | G36: 27823367262 | H36: twillows@mweb.co.za
A37: =IFERROR(VLOOKUP($B37,Company_Cat!$B$2:$E$623,2,FALSE),"") | B37: Lowveld Aircraft Services CC | C37: =IFERROR(VLOOKUP($B37,Company_Cat!$B$2:$H$623,6,FALSE),"") | D37: GARY | E37: VINCENT | G37: 27832940739 | H37: jvincent@vodamail.co.za
A38: =IFERROR(VLOOKUP($B38,Company_Cat!$B$2:$E$623,2,FALSE),"") | B38: PWR Aircraft Maintenance International | C38: =IFERROR(VLOOKUP($B38,Company_Cat!$B$2:$H$623,6,FALSE),"") | D38: Willie | E38: Pienaar | F38: Fixed Wing and Rotorcraft Maintainance Nelspruit | G38: 27827870415 | H38: ns@aminternational.co.za
A39: =IFERROR(VLOOKUP($B39,Company_Cat!$B$2:$E$623,2,FALSE),"") | B39: PWR Aircraft Maintenance International | C39: =IFERROR(VLOOKUP($B39,Company_Cat!$B$2:$H$623,6,FALSE),"") | D39: Willie | E39: Snyman | F39: Fixed Wing and Rotorcraft Maintainance Wonderboom | G39: 27824974687 | H39: wb@aminternational.co.za
A40: =IFERROR(VLOOKUP($B40,Company_Cat!$B$2:$E$623,2,FALSE),"") | B40: PWR Aircraft Maintenance International | C40: =IFERROR(VLOOKUP($B40,Company_Cat!$B$2:$H$623,6,FALSE),"") | D40: Pine | E40: Pienaar | F40: Aircraft Maintainance and Sales | G40: 27833050605 | H40: gm@aminternational.co.za
...

Sheet Company_Notes
A1: C_ID | B1: Company | C1: Order | D1: Notes
A2: =IFERROR(VLOOKUP($B2,Company_Cat!$B$2:$E$623,2,FALSE),"") | B2: Santam Aviation | D2: Santam Aviation (a dedicated division) is widely regarded as South Africa’s leading aviation insurer, covering a wide range of private and corporate aircraft. They are known for financial stability and a strong track record, making them a reliable partner for aircraft coverage.
A3: =IFERROR(VLOOKUP($B3,Company_Cat!$B$2:$E$623,2,FALSE),"") | B3: iTOO Special Risks (Hollard) | D3: heir policies (for hull, third-party liability, etc.) are comprehensive yet simplified, and backed by Hollard’s financial strength.
A4: =IFERROR(VLOOKUP($B4,Company_Cat!$B$2:$E$623,2,FALSE),"") | B4: Old Mutual Insure | D4: Old Mutual’s Specialty Insurance division handles large and niche risks (e.g. engineering, marine) and can insure general aviation as part of bespoke solutions.
A5: =IFERROR(VLOOKUP($B5,Company_Cat!$B$2:$E$623,2,FALSE),"") | B5: Infiniti Insurance | D5: Infiniti’s collaborative approach and growing presence in aviation insurance can be an opportunity – they are open to innovative solutions and have a flexible partnership philosophy
A6: =IFERROR(VLOOKUP($B6,Company_Cat!$B$2:$E$623,2,FALSE),"") | B6: Natsure (Guardrisk) | D6: their aviation insurance solutions (including aircraft hull and liability, drone cover, etc.) are underwritten by Guardrisk Insurance, a leading cell-captive insurer
A7: =IFERROR(VLOOKUP($B7,Company_Cat!$B$2:$E$623,2,FALSE),"") | B7: Natsure (Guardrisk) | D7: Natsure’s broad broker network across Southern Africa means they insure many private and commercial aircraft via various brokers, making them a noteworthy player in GA insurance.
A8: =IFERROR(VLOOKUP($B8,Company_Cat!$B$2:$E$623,2,FALSE),"") | B8: AIG South Africa | D8: AIG’s aerospace division, for instance, offers policies for everything from “small aircraft operators to major airline manufacturers,” with dedicated aviation claims teams worldwide
A9: =IFERROR(VLOOKUP($B9,Company_Cat!$B$2:$E$623,2,FALSE),"") | B9: Lloyd’s of London | D9: active via local brokers
A10: =IFERROR(VLOOKUP($B10,Company_Cat!$B$2:$E$623,2,FALSE),"") | B10: DJA Aviation (Dennis Jankelow & Associates) | D10: DJA is South Africa’s largest dedicated aviation insurance broker, with a team that represents the greatest concentration of aviation insurance expertise on the continent
A11: =IFERROR(VLOOKUP($B11,Company_Cat!$B$2:$E$623,2,FALSE),"") | B11: DJA Aviation (Dennis Jankelow & Associates) | D11: DJA arranges cover for a huge number of private and commercial aircraft owners. They balance cost, coverage, and service for clients, working with various underwriters (Santam, Lloyd’s, etc.)
A12: =IFERROR(VLOOKUP($B12,Company_Cat!$B$2:$E$623,2,FALSE),"") | B12: Airborne Insurance Consultants (PSG Insure) | D12: PSG Insure became one of the biggest aviation brokers after acquiring Airborne Insurance Consultants, which was Africa’s fastest-growing independent aviation specialist
A13: =IFERROR(VLOOKUP($B13,Company_Cat!$B$2:$E$623,2,FALSE),"") | B13: Airborne Insurance Consultants (PSG Insure) | D13: The merged PSG aviation division has a substantial client footprint across South Africa and insures over 1,000 aircraft owners (post-acquisition)
... A32: =IFERROR(VLOOKUP($B32,Company_Cat!$B$2:$E$623,2,FALSE),"") | B32: AIG South Africa | D32: Cost-efficient, flexible protection, and superior hull and liability coverage for owners, operators, and aircraft management companies
A33: =IFERROR(VLOOKUP($B33,Company_Cat!$B$2:$E$623,2,FALSE),"") | B33: AIG South Africa | C33: 1 | D33: Supplier Registration Done - Check AIG Supplier One Dashboard for Appearances etc.
A34: =IFERROR(VLOOKUP($B34,Company_Cat!$B$2:$E$623,2,FALSE),"") | B34: MCC Aviation(PTY) Ltd | D34: Helicopter AMO - Lanseria
A35: =IFERROR(VLOOKUP($B35,Company_Cat!$B$2:$E$623,2,FALSE),"") | B35: Lady Lori Kenya Limited | D35: Luxury helicopter charter and aero‑medical services in East Africa.
A36: =IFERROR(VLOOKUP($B36,Company_Cat!$B$2:$E$623,2,FALSE),"") | B36: Lady Lori Kenya Limited | D36: AMO Services
A37: =IFERROR(VLOOKUP($B37,Company_Cat!$B$2:$E$623,2,FALSE),"") | B37: Ferreira Aviation CC | C37: 1 | D37: Clear indication that they need to be able to order by Serial number - need to convert from Acryl Form
A38: =IFERROR(VLOOKUP($B38,Company_Cat!$B$2:$E$623,2,FALSE),"") | B38: Lowveld Aircraft Services CC | D38: Everyone might be dead or business sold
A39: =IFERROR(VLOOKUP($B39,Company_Cat!$B$2:$E$623,2,FALSE),"")
A40: =IFERROR(VLOOKUP($B40,Company_Cat!$B$2:$E$623,2,FALSE),"")
A41: =IFERROR(VLOOKUP($B41,Company_Cat!$B$2:$E$623,2,FALSE),"")
A42: =IFERROR(VLOOKUP($B42,Company_Cat!$B$2:$E$623,2,FALSE),"")
A43: =IFERROR(VLOOKUP($B43,Company_Cat!$B$2:$E$623,2,FALSE),"")
A44: =IFERROR(VLOOKUP($B44,Company_Cat!$B$2:$E$623,2,FALSE),"")
A45: =IFERROR(VLOOKUP($B45,Company_Cat!$B$2:$E$623,2,FALSE),"")
A46: =IFERROR(VLOOKUP($B46,Company_Cat!$B$2:$E$623,2,FALSE),"")
A47: =IFERROR(VLOOKUP($B47,Company_Cat!$B$2:$E$623,2,FALSE),"")
A48: =IFERROR(VLOOKUP($B48,Company_Cat!$B$2:$E$623,2,FALSE),"")
A49: =IFERROR(VLOOKUP($B49,Company_Cat!$B$2:$E$623,2,FALSE),"")
A50: =IFERROR(VLOOKUP($B50,Company_Cat!$B$2:$E$623,2,FALSE),"")
... A623: =IFERROR(VLOOKUP($B623,Company_Cat!$B$2:$E$623,2,FALSE),"")

Sheet Company_Addresses
A1: C_ID | B1: Company | C1: Type | D1: Airport
A2: =IFERROR(VLOOKUP($B2,Company_Cat!$B$2:$E$623,2,FALSE),"") | B2: Flightsure | C2: Postal | D2: N/A | E2: PO.Box 5072, Halfway House, 1685
A3: =IFERROR(VLOOKUP($B3,Company_Cat!$B$2:$E$623,2,FALSE),"") | B3: Flightsure | C3: Head | E3: Block 2, First Floor South, Waterfall Terraces, Waterfall Park, Bekker Road, Midrand
A4: =IFERROR(VLOOKUP($B4,Company_Cat!$B$2:$E$623,2,FALSE),"") | B4: Arc Aviation (Aircraft Risk Company) | C4: Head | E4: Level 1, Block C, Cedar Tree Office Park, Cnr Cedar Road and Stinkwood Close, Broadacres
A5: =IFERROR(VLOOKUP($B5,Company_Cat!$B$2:$E$623,2,FALSE),"") | B5: AIG South Africa | C5: Joburg | E5: 1st Floor, Sandown Mews West, 88 Stella Street, Sandown 2196 PO Box 31983, Braamfontein 2017, South Africa
A6: =IFERROR(VLOOKUP($B6,Company_Cat!$B$2:$E$623,2,FALSE),"") | B6: Orsmond Aviation | C6: Head | E6: Bethlehem
A7: =IFERROR(VLOOKUP($B7,Company_Cat!$B$2:$E$623,2,FALSE),"") | B7: Capital Air (Pty) Ltd | C7: Head | D7: Rand | E7: Hanger 3H-Rand Airport, Germiston 1401
A8: =IFERROR(VLOOKUP($B8,Company_Cat!$B$2:$E$623,2,FALSE),"") | B8: NAC Helicopter Division | C8: Head | E8: Rand Airport, Lanseria International Airport, Lanseria, 1748
A9: =IFERROR(VLOOKUP($B9,Company_Cat!$B$2:$E$623,2,FALSE),"") | B9: MCC Aviation(PTY) Ltd | C9: Head | E9: Hangar 43, Gate 5, Lanseria International Airport
A10: =IFERROR(VLOOKUP($B10,Company_Cat!$B$2:$E$623,2,FALSE),"") | B10: Transvaal Aircraft Maintenance (Pty) Ltd | C10: Head | E10: 3 Hanger, Wonderboom Airport, Pretoria, 0182
A11: =IFERROR(VLOOKUP($B11,Company_Cat!$B$2:$E$623,2,FALSE),"") | B11: PRECISION AVIATION SERVICES (PTY) Ltd | C11: Head | E11: Hangar 109, Lintvelt Avenue, Wonderboom Airport, Pretoria, 0182P.O. Box 81958, Doornpoort, Pretoria, 0017
A12: =IFERROR(VLOOKUP($B12,Company_Cat!$B$2:$E$623,2,FALSE),"") | B12: BAC Aviation (Pty) Ltd | C12: Head | E12: Imbonini Helistop, 4 Barbet Road, Shakas Head, KZN 4399
A13: =IFERROR(VLOOKUP($B13,Company_Cat!$B$2:$E$623,2,FALSE),"") | B13: Ferreira Aviation CC | C13: Head | E13: Hangar B4, New Tempe Airport, Kenilworth Road, Bainsvlei, Bloemfontein
A14: =IFERROR(VLOOKUP($B14,Company_Cat!$B$2:$E$623,2,FALSE),"") | B14: Ferreira Aviation CC | C14: Satelite | E14: Ferreira Aviation, George Airport, General area, George
A15: =IFERROR(VLOOKUP($B15,Company_Cat!$B$2:$E$623,2,FALSE),"") | B15: Vektor Aviation | C15: Head | E15: 296 Glenwood Road, Lynnwood Park, Pretoria, 0081
A16: =IFERROR(VLOOKUP($B16,Company_Cat!$B$2:$E$623,2,FALSE),"") | B16: Vektor Aviation | C16: Satelite | E16: Block A, Nicol on Main Office Park 2, Bruton Road, Bryanston, Johannesburg
A17: =IFERROR(VLOOKUP($B17,Company_Cat!$B$2:$E$623,2,FALSE),"") | B17: Greystones Aviaton Components (Pty) Ltd | C17: Head | E17: 1146 Chris Hani Road, Durban, 4000
A18: =IFERROR(VLOOKUP($B18,Company_Cat!$B$2:$E$623,2,FALSE),"") | B18: Hover Dynamics Maintenance CC | C18: Head | E18: Hanger M, Grand Central Airport, Midrand
A19: =IFERROR(VLOOKUP($B19,Company_Cat!$B$2:$E$623,2,FALSE),"") | B19: Heli-Fix cc | C19: Head | E19: Hangar 37, Wonderboom Airport, Pretoria 0182PO Box 80602, Doornpoort, Pretoria 0017
... A37: =IFERROR(VLOOKUP($B37,Company_Cat!$B$2:$E$623,2,FALSE),"") | B37: Superior Aeroworx | C37: Head | E37: No 3 New Road, Main Terminal Building, Grand Central Airport, Midrand, Gauteng, 1685, South Africa
A38: =IFERROR(VLOOKUP($B38,Company_Cat!$B$2:$E$623,2,FALSE),"")
A39: =IFERROR(VLOOKUP($B39,Company_Cat!$B$2:$E$623,2,FALSE),"")
A40: =IFERROR(VLOOKUP($B40,Company_Cat!$B$2:$E$623,2,FALSE),"")
A41: =IFERROR(VLOOKUP($B41,Company_Cat!$B$2:$E$623,2,FALSE),"")
A42: =IFERROR(VLOOKUP($B42,Company_Cat!$B$2:$E$623,2,FALSE),"")
A43: =IFERROR(VLOOKUP($B43,Company_Cat!$B$2:$E$623,2,FALSE),"")
A44: =IFERROR(VLOOKUP($B44,Company_Cat!$B$2:$E$623,2,FALSE),"")
A45: =IFERROR(VLOOKUP($B45,Company_Cat!$B$2:$E$623,2,FALSE),"")
A46: =IFERROR(VLOOKUP($B46,Company_Cat!$B$2:$E$623,2,FALSE),"")
A47: =IFERROR(VLOOKUP($B47,Company_Cat!$B$2:$E$623,2,FALSE),"")
A48: =IFERROR(VLOOKUP($B48,Company_Cat!$B$2:$E$623,2,FALSE),"")
A49: =IFERROR(VLOOKUP($B49,Company_Cat!$B$2:$E$623,2,FALSE),"")
... A1000: =IFERROR(VLOOKUP($B1000,Company_Cat!$B$2:$E$623,2,FALSE),"")

Sheet CAA
A1: Midrand Office AMOs (Head Office)
A2: # | B2: AMO Number | C2: NAME | D2: CATEGORIES | E2: MAIN/ SATELLITE | F2: LOCATION | H2: Category | I2: Scope of Work
A3: 1 | B3: 1 | C3: South African Airways Technical SOC | D3: A, B, C, D, W, X, NDT & Special Processes | E3: Main Base | F3: O.R. Tambo - SAAT Area | H3: A | I3: Line maintenance on aircraft airframes (release to service, minor assembly, certifying install and test/ferry flights)
A4: 2 | B4: 2 | C4: Capital Air (Pty) Ltd | D4: B, D, E & W | E4: Main Base | F4: Rand Airport | H4: B | I4: Component-level maintenance for airframes and accessories (rotorcraft excluded from engine)
A5: 3 | B5: 3 | C5: Century Avionics CC | D5: X & W | E5: Main Base | F5: Lanseria | H5: C | I5: On‑wing maintenance for engines (non‑rotorcraft), including test flight release
A6: 4 | B6: 4 | C6: NAC Lanseria | D6: A,B ,C, W & X | E6: Main Base | F6: Lanseria | H6: D | I6: Rack-level engine work (overhaul, repair, modifications), plus manufacture of parts under CAR 21
A7: 5 | B7: 8 | C7: Roesch Aviation | D7: B | E7: Main Base | F7: Lanseria | H7: E | I7: Rotorcraft and rotorcraft‑engine maintenance (airframe/engine installs, overhaul, rotors, test‑flight release)
A8: 6 | B8: 12 | C8: Aircraft Powerplant Company (Pty) Ltd | D8: C, D, X & SPECIAL PROCESSES | E8: Main Base | F8: Wonderboom | H8: W | I8: Installation and maintenance of aircraft electrical, instrument, and radio systems across all aircraft classes
A9: 7 | B9: 22 | C9: Aero Natal (Pty) Ltd | D9: A, B, C, D, | E9: Main Base | F9: Durban-Virginia Airport | H9: X | I9: Overhaul, repair, testing, modification, and limited manufacture of equipment, instruments, components, accessories, auxiliaries, parts (e.g. propellers class X4, welding class X5)
A10: 8 | B10: 27 | C10: NAC Helicopter Division | D10: B, D, E, W , X WELDING & NDT | E10: Main Base | F10: Rand Airport
A11: 9 | B11: 28 | C11: Vector Aerospace Africa (Pty) Ltd | D11: C, D & SPECIAL PROCESSES NDT | E11: Main Base | F11: Lanseria
A12: 10 | B12: 33 | C12: North East Avionics CC | D12: X & W | E12: Main Base | F12: Nelspruit
A13: 11 | B13: 40 | C13: Nicholson Helicopters CC | D13: B & E | E13: Main Base | F13: Rand Airport
A14: 12 | B14: 43 | C14: South African Air Force - 21Squadron | D14: A, C & W | E14: Main Base | F14: Waterkloof AFB
A15: 13 | B15: 48 | C15: Skycare Maintenance | D15: A, B & C | E15: Main Base | F15: Lanseria
A16: 14 | B16: 51 | C16: Dart Aeronautical (Pty) Ltd | D16: X & W | E16: Main Base | F16: Rand Airport
A17: 15 | B17: 52 | C17: SA Airlink | D17: A, B, C, X & W | E17: Main Base | F17: O.R. Tambo
A18: 16 | B18: 53 | C18: Turbine Versions (Pty) Ltd | D18: A, B, C & W | E18: Main Base | F18: Wonderboom
A19: 17 | B19: 54 | C19: Aztec Electronics (Pty) Ltd | D19: X | E19: Main Base | F19: Elandsfontein
A20: 18 | B20: 56 | C20: Lowveld Aircraft Services CC | D20: A, B, C & W | E20: Main Base | F20: Nelspruit
A21: 19 | B21: 57 | C21: Dentec Avionics ( Amended from Complete Avionics Systems (PTY) LTD) | D21: W & X | E21: Main Base | F21: Wonderboom
... A84: 82 | B84: 803 | C84: Lufthanza Technik AG | D84: A, C, D, W, X, NDT & SPECIAL PROCESSES | E84: Main Base | F84: Germany, Hamburg
D85: D, X, NDT & SPECIAL PROCESSES | E85: Satellite-Stations | F85: Germany - Munich
D86: A, B, C, D, W, X, NDT & SPECIAL PROCESSES | F86: Germany - Frankfurt
D87: A, C & W | F87: Malta
D88: A, C & W | F88: Hungary
D89: A, B, C, W & NDT | F89: Bulgaria
D90: B & NDT | F90: UK
D91: A, C & W | F91: Germany-Alzey
A92: 83 | B92: 810 | C92: Blue Bird Aviation | D92: A,C & W | E92: Main Base | F92: Khartoum, Sudan
A93: 84 | B93: 813 | C93: Academy Air | D93: A & C | E93: Main Base | F93: Rand Airport
A94: 85 | B94: 816 | C94: Executive Air Zimbabwe | D94: A, C, W & X | E94: Main Base | F94: Zimbabwe- Prince Charles
A95: 86 | B95: 824 | C95: Starlite Maintenance Durban (Pty) Ltd | D95: B ,E & W | E95: Main Base | F95: Durban-Virginia Airport
A96: 87 | B96: 829 | C96: Turbo Prop Service Centre Uganda Ltd | D96: A, C & W | E96: Main Base | F96: Uganda
A97: 88 | B97: 830 | C97: Heli-Afrique | D97: B & E | E97: Main Base | F97: Rand Airport
A98: 89 | B98: 844 | C98: Superior Millenium Aircraft Engines CC | D98: A, B, C, D & NTCA | E98: Main Base | F98: Springs Airfield
A99: 90 | B99: 846 | C99: Trio Helicopters & Aviation | D99: B & E | E99: Main Base | F99: Lanseria
A100: 91 | B100: 849 | C100: Vector Aerospace Engine Services Atlantic | D100: D & SPECIAL PROCESSES | E100: Main Base | F100: Canada
A101: 92 | B101: 852 | C101: Acher Aviation | D101: B & E | E101: Main Base | F101: Durban-Virginia Airport
A102: 93 | B102: 854 | C102: Ethiopian Airlines | D102: A, B, C, D, W, X & NDT | E102: Main Base | F102: Ethiopian
...

Sheet Aviation Codes
A1: C_ID | B1: Company | C1: Code
A2: =IFERROR(VLOOKUP($B2,Company_Cat!$B$2:$E$623,2,FALSE),"")
A3: =IFERROR(VLOOKUP($B3,Company_Cat!$B$2:$E$623,2,FALSE),"")
A4: =IFERROR(VLOOKUP($B4,Company_Cat!$B$2:$E$623,2,FALSE),"")
A5: =IFERROR(VLOOKUP($B5,Company_Cat!$B$2:$E$623,2,FALSE),"")
A6: =IFERROR(VLOOKUP($B6,Company_Cat!$B$2:$E$623,2,FALSE),"")
A7: =IFERROR(VLOOKUP($B7,Company_Cat!$B$2:$E$623,2,FALSE),"")
A8: =IFERROR(VLOOKUP($B8,Company_Cat!$B$2:$E$623,2,FALSE),"")
A9: =IFERROR(VLOOKUP($B9,Company_Cat!$B$2:$E$623,2,FALSE),"")
A10: =IFERROR(VLOOKUP($B10,Company_Cat!$B$2:$E$623,2,FALSE),"")
A11: =IFERROR(VLOOKUP($B11,Company_Cat!$B$2:$E$623,2,FALSE),"")
A12: =IFERROR(VLOOKUP($B12,Company_Cat!$B$2:$E$623,2,FALSE),"")
A13: =IFERROR(VLOOKUP($B13,Company_Cat!$B$2:$E$623,2,FALSE),"")
... A1000: =IFERROR(VLOOKUP($B1000,Company_Cat!$B$2:$E$623,2,FALSE),"")

Sheet Sheet

Sheet Sheet 1
A1: Insurance | B1: Broker
A2: Santam Aviation, | B2: Aerospace Underwriting Managers
A3: Hollard/iTOO Special Risks,
A4: Bryte Insurance, and
A5: AIG South Africa
A6: Azriel Aviation and
A7: Osprey,
A8: international carriers Global Aerospace and
A9: Allianz Commercial that operate through Johannesburg brokers | B9: Compass Ins.
A10: Global Aerospace
A11: Chubb & WTW

Sheet Flight schools
A1: School | B1: Contact person (role) | C1: Phone | D1: Email | E1: Addresses | F1: Planes | G1: Website | H1: Description type
A2: Lanseria Flight Centre (TBD) | B2: Ian Dyson (Director); Mark Hardcastle (Chief Flight Instructor) | C2: +27 11 312 5166 | D2: info@flylfc.com | H2: HELICOPTER OR LIGHT AIRCRAFT
A3: Aeronav Academy (Lanseria) | B3: Donald O’Connor (Managing Director) | C3: +27 11 701 3862 | D3: info@aeronav.co.za | E3: Friday 03/10/2025 Reach Out
A4: Skyhawk Aviation (Lanseria) | B4: Mohamed Lashin (Chief Flight Instructor) | C4: +27 11 701 2622 | D4: info@skyhawk.co.za
A5: Blue Chip Flight School (Wonderboom, PTA) | B5: Brendon Lubbe (Chief Flight Instructor) | C5: +27 12 543 3050 | D5: marketing@bluechip-avia.co.za
A6: Eagle Air (Wonderboom, PTA) | B6: General contact | C6: Web form | D6: info@eagleair.co.za
A7: Superior Pilot Services (SPS, Grand Central) | B7: General contact | C7: +27 11 805 0605 | D7: info@superiorair.co.za
A8: Flight Training Services – FTS (Grand Central) | B8: General contact | C8: +27 11 805 9015 / 9016 | D8: fly@fts.co.za
A9: Central Flying Academy (Rand, Germiston) | B9: Erna Krebs (Chief Flight Instructor / Director) | C9: +27 11 824 4421 | D9: info@cfasa.co.za
A10: Johannesburg School of Flying (Rand, Germiston) | B10: Siphiwe Richard Khoza (Chief Flight Instructor) | C10: +27 11 827 9827 / 824 3990 | D10: info@jsf.co.za
A11: U-Fly Training Academy (Rand, Germiston) | B11: Dr Robert Gobac (Chief Flying Instructor) | C11: +27 11 824 0680 | D11: info@uflyacademy.co.za
A12: Eagle1 Flight Academy (Rand, Germiston) | B12: DJ Lubbe (Chief Flight Instructor) | C12: +27 11 824 1396; +27 79 448 8289 | D12: info@eagle1.co.za
A13: Airborne Aviation (Brakpan/Benoni) | B13: Seymour “Sluggy” Lugg (Chief Flying Instructor) | C13: +27 74 113 2911 | D13: info@airborneaviation.co.za
A14: Johannesburg Flying Academy (Panorama, Alberton) | B14: Russell Best (Chief Flight Instructor) | C14: +27 64 756 6356 (office); +27 65 969 8873 (Shamir Orrie) | D14: info@jhbflying.co.za
A15: Sun Quest Aviation (Rand, Germiston) | B15: General contact | C15: +27 81 309 3113 | D15: info@sqasa.co.za
... A19: Middelburg Aero Club – Flight School (i-Flight Aviation) Middelburg Airfield (FAMB) | B19: Francois Barnard | C19: +27 63 104 6163 | D19: info@i-flight.co.za
A20: AFOS Flight Training School | B20: Training Office | C20: +27 11 827 4125; +27 83 327 6333 | D20: fly@afos.co.za; mark@afos.co.za | E20: Hangar 40, Lancaster Ave, Rand Airport 1419 | F20: — | G20: http://www.afos.co.za | H20: Fixed-wing training at Rand Airport | I20: Fixed-wing
A21: Aeronav Academy | B21: Admissions Office | C21: +27 11 701 3862 | D21: info@aeronav.co.za | E21: Gate 9A, Lanseria International Airport | F21: Diamond DA20; Cessna 172; Diamond DA42 | G21: https://www.aeronav.co.za | H21: Lanseria ATO; single & multi-engine training; FNPT II | I21: Fixed-wing
A22: Bluebird Aerospace Flight School | B22: Training Office | C22: +27 71 480 4513 | D22: info@bluebirdaerospace.com | E22: Vereeniging Airport (FAVV), 121 Citation Rd, Aeroval | F22: Cessna 150; Cessna 172; Piper Cherokee | G22: https://bluebirdaerospace.com/ | H22: Fixed-wing flight school at Vereeniging | I22: Fixed-wing
A23: Central Flying Academy (CFA) | B23: Erna Krebs (Chief Flight Instructor) | C23: +27 11 824 4421 | D23: info@cfasa.co.za | E23: Hangar 28, Hurricane Rd, Rand Airport, Germiston 1401 | F23: Cessna 172; Cessna 172RG; Piper PA-30 Twin Comanche | G23: https://www.cfasa.co.za | H23: Fixed-wing ATO at Rand Airport; PPL→CPL/IF; FNPT II available | I23: Fixed-wing
A24: Eagle1 Flight Academy | B24: Training Office | C24: +27 11 824 1396; +27 79 448 8289 | D24: info@eagle1.co.za | E24: Hangar 20, Rand Airport, Germiston 1401 | F24: — | G24: https://www.eagle1.co.za | H24: Fixed-wing flight school at Rand Airport | I24: Fixed-wing
A25: Helivate Helicopter Services | B25: Training Team | C25: +27 60 969 3317; +27 72 219 3264; +27 84 583 1569 | D25: info@helivate.com | E25: Jack Taylor Airport, Barta Street, Krugersdorp | F25: Robinson R44; Robinson R66; Alouette III | G25: https://www.helivate.com/ | H25: Helicopter pilot training; Gauteng base at Krugersdorp | I25: Helicopter | K25: paul@helivate.com | L25: paul@statusmark.co.za | M25: Paul Cumming
A26: Henley Air Flight Training | B26: Flight School Office | C26: +27 11 827 5503 | D26: flightschool@henleyair.co.za | E26: Hangar 6, Rand Airport, Germiston 1419 | F26: Robinson R44; Bell 206 JetRanger; Bell 407 | G26: https://www.henleyairflighttraining.co.za/ | H26: Helicopter pilot training (PPL→ATPL) at Rand | I26: Helicopter
A27: Hover Dynamics | B27: Andre Snyman (Head of Training) | C27: +27 11 315 1834 | D27: reception@hoverdynamics.co.za | E27: Grand Central Airport Terminal Building, New Road, Midrand | F27: Robinson R22; Robinson R44; Robinson R66 | G27: https://hoverdynamics.co.za/ | H27: Helicopter pilot training at Grand Central | I27: Helicopter | K27: hdm@hoverdynamics.co.za | L27: ame@hoverdynamics.co.za | M27: DEAN | N27: FELDMAN | O27: dean@hoverdynamics.co.za
A28: Johannesburg School of Flying (JSF) | B28: Training Office | C28: +27 11 827 9827; +27 11 824 3990 | D28: info@jsf.co.za | E28: Hangars 30–33, Rand Airport, Germiston 1401 | F28: Cessna 152; Cessna 172; Piper PA-34 Seneca II | G28: https://jsf.co.za | H28: Fixed-wing training at Rand Airport; multi-engine available | I28: Fixed-wing
A29: Lanseria Flight Centre (LFC) | B29: Ian Dyson (Director) | C29: +27 11 312 5166; +27 60 829 0953 | D29: info@flylfc.com | E29: Terminal Building, Office Suite 25B, Grand Central Airport, Midrand | F29: Cessna 172; Diamond DA42; Piper PA-34 Seneca | G29: https://www.flylfc.com | H29: Fixed-wing training at Grand Central; integrated & modular | I29: Fixed-wing
A30: NAC Helicopter Flight Training (National Airways Corporation) | B30: Vicky Sankey (Training/Exams) | C30: +27 11 345 2500 | D30: flightschool@nac.co.za; info@nac.co.za | E30: Rand Airport, Germiston (Training) & Ultimate Heliport, Midrand | F30: Robinson R22; Robinson R44; Bell 206/407 | G30: https://www.nac.co.za/helicopter-pilot-training | H30: Helicopter flight training (NAC) | I30: Helicopter
A31: Phoebus Apollo Aviation (Flight School) | B31: Flight School Office | C31: +27 11 824 3814 | D31: flightschool@phoebusapollo.co.za | E31: Hangars 17 & 21, Rand Airport, Germiston 1401 | F31: Cessna 152; Cessna 172/172RG; Piper PA-34 Seneca I | G31: https://www.phoebusapollo.co.za | H31: Fixed-wing training and charter | I31: Fixed-wing
A32: Skyhawk Aviation | B32: Training Office | C32: +27 11 701 2622 | D32: info@skyhawk.co.za | E32: Hangar 30, Gate 5, Lanseria International Airport | F32: Cessna 172; Piper PA-28; Piper PA-34 Seneca | G32: https://skyhawk.co.za | H32: Fixed-wing training; career pilot programmes | I32: Fixed-wing
A33: Sun Quest Aviation (SQA) | B33: Ops/Enquiries | C33: +27 81 309 3113; +27 11 827 9308 | D33: info@sqasa.co.za | E33: Hangar 4, Rand Airport, Germiston 1401 | F33: — | G33: https://sqasa.co.za/ | H33: Fixed-wing ATO at Rand Airport | I33: Fixed-wing
A34: U-Fly Training Academy | B34: Training Office | C34: +27 11 824 0680; +27 11 027 7655 | D34: info@uflyacademy.co.za | E34: 1 Spitfire Crescent, Rand Airport, Germiston | F34: Piper PA-28 Warrior; Piper PA-28R Arrow; Piper PA-34 Seneca | G34: https://www.uflyacademy.co.za | H34: Fixed-wing training and hire-&-fly; PPL→ATPL pathway | I34: Fixed-wing
A35: Superior Pilot Services (SPS) | B35: Training Office | C35: +27 11 805 0605 | D35: info@superiorair.co.za | E35: Grand Central Airport (FAGC), Midrand, Gauteng | F35: Cessna 172 | G35: https://www.superiorpilotservices.com | H35: Fixed-wing ATO at Grand Central; PPL, Night, CPL etc. | I35: Fixed-wing
A36: Flight Training Services (FTS) | B36: Training Office | C36: +27 11 805 9015 | D36: fly@fts.co.za | E36: Grand Central Airport (FAGC), Midrand, Gauteng | F36: Cessna 172 | G36: https://www.fts.co.za | H36: Fixed-wing ATO; PPL through CPL/IR; based at Grand Central. | I36: Fixed-wing
A37: Blue Chip Flight School | B37: Training Office | C37: +27 12 543 3050 | D37: marketing@bluechip-avia.co.za | E37: Main Terminal Building, Wonderboom National Airport (FAWB), Pretoria | F37: Cessna 172 | G37: https://bluechipflightschool.co.za | H37: Large Wonderboom-based ATO offering PPL → CPL/IR. | I37: Fixed-wing
A38: Eagle Air Flight School | B38: Training Office | C38: +27 12 543 1929 | D38: info@eagleair.co.za | E38: Wonderboom National Airport (FAWB), Pretoria | F38: Cessna 172; Piper PA-28; Beechcraft Baron | G38: https://eagleair.co.za | H38: Comprehensive fixed-wing training at Wonderboom. | I38: Fixed-wing
A39: Loutzavia Flight Training Academy | B39: Training Office | C39: +27 12 543 1620 | D39: info@loutzavia.co.za | E39: Wonderboom National Airport (FAWB), Pretoria | F39: (not publicly listed on site) | G39: https://loutzavia.com | H39: Fixed-wing ATO; PPL → advanced ratings at Wonderboom. | I39: Fixed-wing
... A41: Professional Flight Centre (PFC) | B41: Training Office | C41: +27 12 567 0575 | D41: pfc1161@gmail.com | E41: Wonderboom National Airport (FAWB), Pretoria | F41: Cessna 172 | G41: https://www.professionalflightcentre.co.za | H41: Fixed-wing ATO at Wonderboom; PPL, Night, CPL. | I41: Fixed-wing
A42: Flyfofa Aviation & Training | B42: Training Office | C42: +27 12 543 5798 | D42: info@flyfofa.co.za | E42: Wonderboom National Airport (FAWB), Pretoria | F42: (not publicly listed on site) | G42: https://flyfofa.co.za | H42: Fixed-wing ATO at Wonderboom; ab-initio and advanced. | I42: Fixed-wing | K42: BRUCE | L42: FISHA | M42: fisha@flyfofa.co.za | N42: bfisha@flyfofa.co.za | O42: reception@flyfofa.co.za | R42: Website: https://www.flyfofa.co.za
A43: Airborne Aviation (Brakpan) | B43: Training Office | C43: +27 76 564 2722 | D43: info@airborne-aviation.co.za | E43: Brakpan/Benoni Airfield (FABB), Gauteng | F43: Cessna 172; Cessna 182; Piper Seneca | G43: https://airborne-aviation.co.za | H43: Fixed-wing ATO at Brakpan/Benoni; PPL → CPL/ME. | I43: Fixed-wing
A44: Mach1 Aviation Flight Academy | B44: Training Office | C44: +27 11 743 3305 | D44: info@mach1aviation.co.za | E44: Springs Airfield (FASI), Springs, Gauteng | F44: (not publicly listed on site) | G44: https://www.mach1aviation.co.za | H44: Fixed-wing ATO at Springs; PPL → CPL with on-site lodging. | I44: Fixed-wing
...

Sheet FL extended
A1: Aeronav Academy (Lanseria) | C1: Sent
A2: Donald O'Connor | B2: donald@aeronav.co.za | C2: x
A3: Donald O' Connor | B3: donald.oconnor@aeronav.co.za | C3: x | E3: Friday 03/10/2025 Reach Out
B4: info@aeronav.co.za
A5: Central Flying Academy (Rand, Germiston)
A6: BARTER PAUL RONALD | B6: paul@cfa.co.za | C6: x
A7: MARAIS WILLEM KAREL NICOLAAS | B7: willie@cfa.co.za | C7: x
B8: info@cfasa.co.za
A10: Airborne Aviation (Brakpan/Benoni) | B10: sam@airborneaviation.co.za | C10: x
D16: info@mach1aviation.co.za
A20: AFOS Flight Training School | B20: Training Office | C20: +27 11 827 4125; +27 83 327 6333 | D20: fly@afos.co.za; mark@afos.co.za | E20: Hangar 40, Lancaster Ave, Rand Airport 1419 | F20: — | G20: http://www.afos.co.za | H20: Fixed-wing training at Rand Airport | I20: Fixed-wing
A21: Aeronav Academy | B21: Admissions Office | C21: +27 11 701 3862 | D21: info@aeronav.co.za | E21: Gate 9A, Lanseria International Airport | F21: Diamond DA20; Cessna 172; Diamond DA42 | G21: https://www.aeronav.co.za | H21: Lanseria ATO; single & multi-engine training; FNPT II | I21: Fixed-wing
A22: Bluebird Aerospace Flight School | B22: Training Office | C22: +27 71 480 4513 | D22: info@bluebirdaerospace.com | E22: Vereeniging Airport (FAVV), 121 Citation Rd, Aeroval | F22: Cessna 150; Cessna 172; Piper Cherokee | G22: https://bluebirdaerospace.com/ | H22: Fixed-wing flight school at Vereeniging | I22: Fixed-wing
A23: Central Flying Academy (CFA) | B23: Erna Krebs (Chief Flight Instructor) | C23: +27 11 824 4421 | D23: info@cfasa.co.za | E23: Hangar 28, Hurricane Rd, Rand Airport, Germiston 1401 | F23: Cessna 172; Cessna 172RG; Piper PA-30 Twin Comanche | G23: https://www.cfasa.co.za | H23: Fixed-wing ATO at Rand Airport; PPL→CPL/IF; FNPT II available | I23: Fixed-wing
A24: Eagle1 Flight Academy | B24: Training Office | C24: +27 11 824 1396; +27 79 448 8289 | D24: info@eagle1.co.za | E24: Hangar 20, Rand Airport, Germiston 1401 | F24: — | G24: https://www.eagle1.co.za | H24: Fixed-wing flight school at Rand Airport | I24: Fixed-wing
A25: Helivate Helicopter Services | B25: Training Team | C25: +27 60 969 3317; +27 72 219 3264; +27 84 583 1569 | D25: info@helivate.com | E25: Jack Taylor Airport, Barta Street, Krugersdorp | F25: Robinson R44; Robinson R66; Alouette III | G25: https://www.helivate.com/ | H25: Helicopter pilot training; Gauteng base at Krugersdorp | I25: Helicopter | K25: paul@helivate.com | L25: paul@statusmark.co.za | M25: Paul Cumming
A26: Henley Air Flight Training | B26: Flight School Office | C26: +27 11 827 5503 | D26: flightschool@henleyair.co.za | E26: Hangar 6, Rand Airport, Germiston 1419 | F26: Robinson R44; Bell 206 JetRanger; Bell 407 | G26: https://www.henleyairflighttraining.co.za/ | H26: Helicopter pilot training (PPL→ATPL) at Rand | I26: Helicopter
A27: Hover Dynamics | B27: Andre Snyman (Head of Training) | C27: +27 11 315 1834 | D27: cfi@hoverdynamics.co.za; reception@hoverdynamics.co.za | E27: Grand Central Airport Terminal Building, New Road, Midrand | F27: Robinson R22; Robinson R44; Robinson R66 | G27: https://hoverdynamics.co.za/ | H27: Helicopter pilot training at Grand Central | I27: Helicopter | K27: hdm@hoverdynamics.co.za | L27: ame@hoverdynamics.co.za | M27: DEAN | N27: FELDMAN | O27: dean@hoverdynamics.co.za
A28: Johannesburg School of Flying (JSF) | B28: Training Office | C28: +27 11 827 9827; +27 11 824 3990 | D28: info@jsf.co.za | E28: Hangars 30–33, Rand Airport, Germiston 1401 | F28: Cessna 152; Cessna 172; Piper PA-34 Seneca II | G28: https://jsf.co.za | H28: Fixed-wing training at Rand Airport; multi-engine available | I28: Fixed-wing
A29: Lanseria Flight Centre (LFC) | B29: Ian Dyson (Director) | C29: +27 11 312 5166; +27 60 829 0953 | D29: info@flylfc.com | E29: Terminal Building, Office Suite 25B, Grand Central Airport, Midrand | F29: Cessna 172; Diamond DA42; Piper PA-34 Seneca | G29: https://www.flylfc.com | H29: Fixed-wing training at Grand Central; integrated & modular | I29: Fixed-wing
A30: NAC Helicopter Flight Training (National Airways Corporation) | B30: Vicky Sankey (Training/Exams) | C30: +27 11 345 2500 | D30: flightschool@nac.co.za; info@nac.co.za | E30: Rand Airport, Germiston (Training) & Ultimate Heliport, Midrand | F30: Robinson R22; Robinson R44; Bell 206/407 | G30: https://www.nac.co.za/helicopter-pilot-training | H30: Helicopter flight training (NAC) | I30: Helicopter
A31: Phoebus Apollo Aviation (Flight School) | B31: Flight School Office | C31: +27 11 824 3814 | D31: flightschool@phoebusapollo.co.za | E31: Hangars 17 & 21, Rand Airport, Germiston 1401 | F31: Cessna 152; Cessna 172/172RG; Piper PA-34 Seneca I | G31: https://www.phoebusapollo.co.za | H31: Fixed-wing training and charter | I31: Fixed-wing
A32: Skyhawk Aviation | B32: Training Office | C32: +27 11 701 2622 | D32: info@skyhawk.co.za | E32: Hangar 30, Gate 5, Lanseria International Airport | F32: Cessna 172; Piper PA-28; Piper PA-34 Seneca | G32: https://skyhawk.co.za | H32: Fixed-wing training; career pilot programmes | I32: Fixed-wing
A33: Sun Quest Aviation (SQA) | B33: Ops/Enquiries | C33: +27 81 309 3113; +27 11 827 9308 | D33: info@sqasa.co.za | E33: Hangar 4, Rand Airport, Germiston 1401 | F33: — | G33: https://sqasa.co.za/ | H33: Fixed-wing ATO at Rand Airport | I33: Fixed-wing
A34: U-Fly Training Academy | B34: Training Office | C34: +27 11 824 0680; +27 11 027 7655 | D34: info@uflyacademy.co.za | E34: 1 Spitfire Crescent, Rand Airport, Germiston | F34: Piper PA-28 Warrior; Piper PA-28R Arrow; Piper PA-34 Seneca | G34: https://www.uflyacademy.co.za | H34: Fixed-wing training and hire-&-fly; PPL→ATPL pathway | I34: Fixed-wing
A35: Superior Pilot Services (SPS) | B35: Training Office | C35: +27 11 805 0605 | D35: info@superiorair.co.za | E35: Grand Central Airport (FAGC), Midrand, Gauteng | F35: Cessna 172 | G35: https://www.superiorpilotservices.com | H35: Fixed-wing ATO at Grand Central; PPL, Night, CPL etc. | I35: Fixed-wing
A36: Flight Training Services (FTS) | B36: Training Office | C36: +27 11 805 9015 | D36: fly@fts.co.za | E36: Grand Central Airport (FAGC), Midrand, Gauteng | F36: Cessna 172 | G36: https://www.fts.co.za | H36: Fixed-wing ATO; PPL through CPL/IR; based at Grand Central. | I36: Fixed-wing
A37: Blue Chip Flight School | B37: Training Office | C37: +27 12 543 3050 | D37: marketing@bluechip-avia.co.za | E37: Main Terminal Building, Wonderboom National Airport (FAWB), Pretoria | F37: Cessna 172 | G37: https://bluechipflightschool.co.za | H37: Large Wonderboom-based ATO offering PPL → CPL/IR. | I37: Fixed-wing
A38: Eagle Air Flight School | B38: Training Office | C38: +27 12 543 1929 | D38: info@eagleair.co.za | E38: Wonderboom National Airport (FAWB), Pretoria | F38: Cessna 172; Piper PA-28; Beechcraft Baron | G38: https://eagleair.co.za | H38: Comprehensive fixed-wing training at Wonderboom. | I38: Fixed-wing
A39: Loutzavia Flight Training Academy | B39: Training Office | C39: +27 12 543 1620 | D39: info@loutzavia.co.za | E39: Wonderboom National Airport (FAWB), Pretoria | F39: (not publicly listed on site) | G39: https://loutzavia.com | H39: Fixed-wing ATO; PPL → advanced ratings at Wonderboom. | I39: Fixed-wing
... A41: Professional Flight Centre (PFC) | B41: Training Office | C41: +27 12 567 0575 | D41: pfc1161@gmail.com | E41: Wonderboom National Airport (FAWB), Pretoria | F41: Cessna 172 | G41: https://www.professionalflightcentre.co.za | H41: Fixed-wing ATO at Wonderboom; PPL, Night, CPL. | I41: Fixed-wing
A42: Flyfofa Aviation & Training | B42: Training Office | C42: +27 12 543 5798 | D42: info@flyfofa.co.za | E42: Wonderboom National Airport (FAWB), Pretoria | F42: (not publicly listed on site) | G42: https://flyfofa.co.za | H42: Fixed-wing ATO at Wonderboom; ab-initio and advanced. | I42: Fixed-wing | K42: BRUCE | L42: FISHA | M42: fisha@flyfofa.co.za | N42: bfisha@flyfofa.co.za | O42: reception@flyfofa.co.za
A43: Airborne Aviation (Brakpan) | B43: Training Office | C43: +27 76 564 2722 | D43: info@airborne-aviation.co.za | E43: Brakpan/Benoni Airfield (FABB), Gauteng | F43: Cessna 172; Cessna 182; Piper Seneca | G43: https://airborne-aviation.co.za | H43: Fixed-wing ATO at Brakpan/Benoni; PPL → CPL/ME. | I43: Fixed-wing
A44: Mach1 Aviation Flight Academy | B44: Training Office | C44: +27 11 743 3305 | D44: info@mach1aviation.co.za | E44: Springs Airfield (FASI), Springs, Gauteng | F44: (not publicly listed on site) | G44: https://www.mach1aviation.co.za | H44: Fixed-wing ATO at Springs; PPL → CPL with on-site lodging. | I44: Fixed-wing
A45: Aviatech FAPS Flight Academy | B45: Training Office | C45: +27 83 235 8043 | D45: info@fapsflightacademy.co.za | E45: Potchefstroom Airfield (FAPS), North West | F45: (not publicly listed on site) | G45: https://fapsflightacademy.co.za | H45: Fixed-wing ATO at Potchefstroom; PPL and advanced. | I45: Fixed-wing
A46: Apex Flight Academy (Bucephalus Air) | B46: Training Office | C46: +27 76 692 7352 | D46: info@bucephalusair.co.za | E46: Klerksdorp Airfield (FAKD), North West | F46: (not publicly listed on site) | G46: https://bucephalusair.co.za | H46: Fixed-wing ATO at Klerksdorp; ab-initio to advanced. | I46: Fixed-wing
A47: Witbank Aeronautical Association Flight School | B47: Training Office | C47: +27 82 976 4103 | D47: info@witbankaeroclub.co.za | E47: Witbank Airport (FAWI), Emalahleni, Mpumalanga | F47: (not publicly listed on site) | G47: https://www.facebook.com/groups/WitbankAero | H47: Club-based flight training at Witbank (fixed-wing). | I47: Fixed-wing
A48: Johannesburg Flying Academy | B48: Training Office | C48: +27 82 201 6230 | D48: info@jhbflying.co.za | E48: Panorama Airfield, Johannesburg South (Eikenhof), Gauteng | F48: (not publicly listed on site) | G48: https://www.jhbflying.co.za | H48: Fixed-wing ATO at Panorama; PPL, Night, hour-building. | I48: Fixed-wing
A49: Accolade Flying Wings (Rand) | B49: Training Office | C49: +27 60 985 6622 | D49: info@accoladeflyingwings.co.za | E49: Hangar 54, Rand Airport, 4 Viking Way, Germiston, Gauteng | F49: Tecnam P92; Cessna 172 (Jet-A1); Diamond DA42 | G49: https://accoladeflyingwings.co.za | H49: Fixed-wing ATO at Rand; PPL → CPL/ME; diversified training fleet. | I49: Fixed-wing

Sheet 10-10-25 Capture
B1: School | C1: Contact person (role) | D1: Phone | E1: Email | F1: Addresses | G1: Planes | H1: Website | I1: Description | J1: Type
B2: 43 Air School | C2: Attie Niemann — Chief Executive Officer | D2: +27 46 604 3600 | E2: fly@43airschool.com | F2: Port Alfred Campus, Private Bag X43, Port Alfred 6170 | G2: Cessna 172; Piper PA-28; Beechcraft Baron (multi) | H2: https://www.43airschool.com/ | I2: Large integrated ATO with multi-base operations and Boeing-approved ATPL programs. | J2: Fixed-wing
B3: Progress Flight Academy | C3: John English — CEO Owner | D3: +27 41 451 1196 | E3: info@flightacademy.co.za | F3: Port Elizabeth International Airport, Walmer, Gqeberha | G3: Piper Warrior III (PA-28-161); Cessna 172; Piper Seneca | H3: https://www.flightacademy.co.za/ | I3: Professional pilot training at Gqeberha (Port Elizabeth) with proven fleet for airline pathways. | J3: Fixed-wing
B4: Algoa Flying Club (Flight School) | C4: Michael Thompson — Chief Flying Instructor | D4: +27 41 581 3274 | E4: info@algoafc.co.za | F4: Port Elizabeth International Airport, 10 Forest Hill Dr, Walmer, Gqeberha | G4: Cessna 172; Sling 2; Piper Arrow (PA-28R) | H4: https://algoafc.co.za/flight-school/ | I4: Not‑for‑profit flying club with SACAA ATO; long-standing ab‑initio to advanced training. | J4: Fixed-wing
B5: Madiba Bay School of Flight | C5: Gerhard van Eeden — Owner Accountable Manager | D5: +27 41 581 2040 | E5: info@madibabayschoolofflight.co.za | F5: Port Elizabeth International Airport, Gqeberha | G5: Sling 2; Cessna 172; Piper Twin Comanche (PA-30) | H5: https://www.madibabayschoolofflight.co.za/ | I5: Ab‑initio to advanced training with Sling and legacy Piper types. | J5: Fixed-wing
B6: Aptrac Aviation | C6: Ian Judd — Chief Flight Instructor | D6: +27 41 581 0300 | E6: info@aptrac.co.za | F6: Port Elizabeth, Eastern Cape | G6: Cessna 172; Piper PA-28; Robinson R22 | H6: https://www.bestaviation.net/school/aptrac_aviation/ | I6: Fixed‑wing and helicopter training (per directory listing). | J6: Fixed-wing and Helicopter
